<?xml version="1.0" ?>
<robot name="caretta" xmlns:xacro="http://ros.org/wiki/xacro">

  <material name="blue">
    <color rgba="0.0 0.0 0.8 1.0"/>
  </material>
  <material name="grey">
    <color rgba="0.5 0.5 0.5 1.0"/>
  </material>
  <material name="red">
    <color rgba="0.8 0.0 0.0 1.0"/>
  </material>
  <material name="purple">
    <color rgba="1.0 0.02 1.0 1.0"/>
  </material>
  <material name="white">
    <color rgba="1.0 1.0 1.0 1.0"/>
  </material>

  <link name="base_footprint"/>

  <joint name="base_joint" type="fixed">
    <parent link="base_footprint"/>
    <child link="base_link"/>
    <origin xyz="0.0 0.0 0.03425" rpy="0 0 0"/>
  </joint>
  <link name="base_link">
    <visual>
      <origin xyz="0 0 0.028" rpy="0 0 0"/>
      <geometry>
        <mesh filename="package://rosrider_gazebo/models/common/meshes/caretta.stl" scale="0.001 0.001 0.001"/>
      </geometry>
      <material name="red"/>
    </visual>
    <collision>
      <origin xyz="0 0 0.028" rpy="0 0 0"/>
      <geometry>
        <mesh filename="package://rosrider_gazebo/models/common/meshes/caretta.stl" scale="0.001 0.001 0.001"/>
      </geometry>
    </collision>
    <inertial>
      <origin xyz="0 0 0" rpy="0 0 0"/>
      <mass value="2.2"/>
      <inertia ixx="0.005172767490" ixy="-2.116395632406e-5" ixz="-0.000113099104" iyy="0.003997965711" iyz="-2.287145173874e-5" izz="0.008669583297" />
    </inertial>
  </link>
  <joint name="wheel_left_joint" type="continuous">
    <parent link="base_link"/>
    <child link="wheel_left_link"/>
    <origin xyz="0.0 0.092 0.0" rpy="-1.57 0 0"/>
    <axis xyz="0 0 1"/>
  </joint>
  <link name="wheel_left_link">
    <visual>
      <origin xyz="0 0 0" rpy="1.57 0 0"/>
      <geometry>
        <mesh filename="package://rosrider_gazebo/models/common/meshes/wheel_left.stl" scale="0.001 0.001 0.001"/>
      </geometry>
      <material name="grey"/>
    </visual>
    <collision>
      <origin xyz="0 0 0" rpy="0 0 0"/>
      <geometry>
        <cylinder length="0.022" radius="0.03425"/>
      </geometry>
    </collision>
    <inertial>
      <mass value="0.06" />
      <inertia ixx="2.29346485819975E-05" ixy="0" ixz="0"  iyy="4.19370640001351E-05" iyz="0" izz="2.29346485819975E-05" />
    </inertial>
  </link>

  <joint name="wheel_right_joint" type="continuous">
    <parent link="base_link"/>
    <child link="wheel_right_link"/>
    <origin xyz="0.0 -0.092 0.0" rpy="-1.57 0 0"/>
    <axis xyz="0 0 1"/>
  </joint>
  <link name="wheel_right_link">
    <visual>
      <origin xyz="0 0 0" rpy="1.57 0 0"/>
      <geometry>
        <mesh filename="package://rosrider_gazebo/models/common/meshes/wheel_right.stl" scale="0.001 0.001 0.001"/>
      </geometry>
      <material name="grey"/>
    </visual>
    <collision>
      <origin xyz="0 0 0" rpy="0 0 0"/>
      <geometry>
        <cylinder length="0.022" radius="0.03425"/>
      </geometry>
    </collision>
    <inertial>
      <mass value="0.06" />
      <inertia ixx="2.29346485819975E-05" ixy="0" ixz="0"  iyy="4.19370640001351E-05" iyz="0" izz="2.29346485819975E-05" />
    </inertial>
  </link>

  <joint name="caster_back_joint" type="fixed">
    <parent link="base_link"/>
    <child link="caster_back_link"/>
    <origin xyz="-0.1454 0 -0.02225" rpy="0 0 0"/>
  </joint>
  <link name="caster_back_link">
    <visual>
      <geometry>
        <sphere radius="0.012"/>
      </geometry>
      <material name="white"/>
    </visual>
    <collision>
      <origin xyz="0 0 0" rpy="0 0 0"/>
      <geometry>
        <sphere radius="0.012"/>
      </geometry>
    </collision>
    <inertial>
      <origin xyz="0 0 0" />
      <mass value="0.1" />
      <inertia ixx="0.001" ixy="0.0" ixz="0.0"  iyy="0.001" iyz="0.0" izz="0.001" />
    </inertial>
  </link>

  <joint name="imu_joint" type="fixed">
    <parent link="base_link"/>
    <child link="imu_link"/>
    <origin xyz="-0.056 0.078 0.0396" rpy="0 0 0"/>
  </joint>
  <link name="imu_link">
    <visual>
      <origin xyz="0 0 0" rpy="0 0 0"/>
      <geometry>
        <box size="0.04 0.03 0.0016"/>
      </geometry>
      <material name="purple"/>
    </visual>
  </link>

  <joint name="scan_joint" type="fixed">
    <parent link="base_link"/>
    <child link="base_scan"/>
    <origin xyz="-0.063 0 0.052" rpy="0 0 0"/>
  </joint>
  <link name="base_scan">
    <visual>
      <origin xyz="0 0 0.0" rpy="0 0 0"/>
      <geometry>
        <cylinder length="0.022" radius="0.0328"/>
      </geometry>
      <material name="blue"/>
    </visual>
    <collision>
      <origin xyz="0 0 0.0" rpy="0 0 0"/>
      <geometry>
        <cylinder length="0.022" radius="0.0328"/>
      </geometry>
    </collision>
    <inertial>
      <mass value="0.2" />
      <origin xyz="0 0 0" />
      <inertia ixx="0.001" ixy="0.0" ixz="0.0"  iyy="0.001" iyz="0.0" izz="0.001" />
    </inertial>
  </link>

</robot>